<mujoco model="panda">
  <compiler angle="radian" meshdir="assets" autolimits="true"/>

  <default>
    <default class="panda">
      <material specular="0.5" shininess="0.25"/>
      <joint range="-2.8973 2.8973"/>
      <default class="finger">
        <joint axis="0 1 0" type="slide" range="0 0.04"/>
      </default>

      <default class="collision">
        <geom type="mesh" group="2"/>
          <default class="fingertip_collision_1">
            <geom type="box" size="0.011 0.0075 0.01" pos="0 0.0185 0.011"/>
          </default>
          <default class="fingertip_collision_2">
            <geom type="box" size="0.011 0.0044 0.0019" pos="0 0.0068 0.0022"/>
          </default>
          <default class="fingertip_collision_3">
            <geom type="box" size="0.00875 0.0035 0.01175" pos="0 0.0159 0.02835" quat="1 0.25 0 0"/>
          </default>
          <default class="fingertip_pad_collision_1">
            <geom type="box" size="0.0085 0.004 0.0085" pos="0 0.0055 0.0445"/>
          </default>
          <default class="fingertip_pad_collision_2">
            <geom type="box" size="0.003 0.002 0.003" pos="0.0055 0.002 0.05"/>
          </default>
          <default class="fingertip_pad_collision_3">
            <geom type="box" size="0.003 0.002 0.003" pos="-0.0055 0.002 0.05"/>
          </default>
          <default class="fingertip_pad_collision_4">
            <geom type="box" size="0.003 0.002 0.0035" pos="0.0055 0.002 0.0395"/>
          </default>
        <default class="fingertip_pad_collision_5">
          <geom type="box" size="0.003 0.002 0.0035" pos="-0.0055 0.002 0.0395"/>
        </default>
        <default class="fingertip_pad_collision_6">
          <geom type="box" size="0.00875 0.0076 0.00825" pos="0 0.00758 0.04525"/>
        </default>
      </default>
    </default>
  </default>

  <asset>
    <material class="panda" name="white" rgba="1 1 1 1"/>
    <material class="panda" name="off_white" rgba="0.901961 0.921569 0.929412 1"/>
    <material class="panda" name="black" rgba="0.25 0.25 0.25 1"/>
    <material class="panda" name="green" rgba="0 1 0 1"/>
    <material class="panda" name="light_blue" rgba="0.039216 0.541176 0.780392 1"/>
  </asset>

  <worldbody>
    <!-- <light name="top" pos="0 0 2" mode="trackcom" castshadow="false"/> -->
    <!-- <camera name="front_cam" pos="1.1 0 0.5" xyaxes="0 1 0 -0.4 0 0.7"/> -->
    <body name="link0" childclass="panda">
      <inertial mass="0.629769" pos="0 0 0"
        fullinertia="0.00315 0.00388 0.004285 8.2904e-7 0.00015 8.2299e-6"/>
      <geom name="link0_capsule_collision" type="capsule" class="collision" size="0.08 0.01" pos="0 0 0.06"/>
      <body name="link1" pos="0 0 0.333">
        <inertial mass="4.970684" pos="0.003875 0.002081 -0.04762"
          fullinertia="0.70337 0.70661 0.0091170 -0.00013900 0.0067720 0.019169"/>
        <joint name="joint1" range="-2.8973 2.8973"/>
        <geom name="link1_capsule_collision" type="capsule" class="collision" size="0.07 0.08" pos="0 -0.03 -0.08" quat="0.9 0.1 0 0"/>
        <body name="link2" quat="1 -1 0 0">
          <inertial mass="0.646926" pos="-0.003141 -0.02872 0.003495"
            fullinertia="0.0079620 2.8110e-2 2.5995e-2 -3.925e-3 1.0254e-2 7.04e-4"/>
          <joint name="joint2" range="-1.7628 1.7628"/>
          <geom name="link2_capsule_collision" type="capsule" class="collision" size="0.06 0.09" pos="0 -0.075 0.03" quat="0.6 -0.4 0 0"/>
          <body name="link3" pos="0 -0.316 0" quat="1 1 0 0">
            <joint name="joint3" range="-2.8973 2.8973"/>
            <inertial mass="3.228604" pos="2.7518e-2 3.9252e-2 -6.6502e-2"
              fullinertia="3.7242e-2 3.6155e-2 1.083e-2 -4.761e-3 -1.1396e-2 -1.2805e-2"/>
            <geom name="link3_capsule_collision" type="capsule" class="collision" size="0.06 0.07" pos="0.02 0.03 -0.05" quat="0.7 0 0.3 0"/>
            <body name="link4" pos="0.0825 0 0" quat="1 1 0 0">
              <inertial mass="3.587895" pos="-5.317e-2 1.04419e-1 2.7454e-2"
                fullinertia="2.5853e-2 1.9552e-2 2.8323e-2 7.796e-3 -1.332e-3 8.641e-3"/>
              <joint name="joint4" range="-3.0718 -0.0698"/>
              <geom name="link4_capsule_collision" type="capsule" class="collision" size="0.06 0.07" pos="-0.04 0.05 0.02" quat="1 0 1 -0.7"/>
              <body name="link5" pos="-0.0825 0.384 0" quat="1 -1 0 0">
                <inertial mass="1.225946" pos="-1.1953e-2 4.1065e-2 -3.8437e-2"
                  fullinertia="3.5549e-2 2.9474e-2 8.627e-3 -2.117e-3 -4.037e-3 2.29e-4"/>
                <joint name="joint5" range="-2.8973 2.8973"/>
                <geom name="link5_capsule_collision" type="capsule" class="collision" size="0.05 0.11" pos="0 0.04 -0.12"/>
                <body name="link6" quat="1 1 0 0">
                  <inertial mass="1.666555" pos="6.0149e-2 -1.4117e-2 -1.0517e-2"
                    fullinertia="1.964e-3 4.354e-3 5.433e-3 1.09e-4 -1.158e-3 3.41e-4"/>
                  <joint name="joint6" range="-0.0175 3.7525"/>
                  <geom name="link6_capsule_collision" type="capsule" class="collision" size="0.06 0.03" pos="0.04 0 0" quat="1 0 1 0"/>
                  <body name="link7" pos="0.088 0 0" quat="1 1 0 0">
                    <inertial mass="7.35522e-01" pos="1.0517e-2 -4.252e-3 6.1597e-2"
                      fullinertia="1.2516e-2 1.0027e-2 4.815e-3 -4.28e-4 -1.196e-3 -7.41e-4"/>
                    <joint name="joint7" range="-2.8973 2.8973"/>
                    <geom name="link7_capsule_collision" type="capsule" class="collision" size="0.05 0.04" pos="0 0 0.04"/>
                    <body name="hand" pos="0 0 0.107" quat="0.9238795 0 0 -0.3826834">
                      <inertial mass="0.73" pos="-0.01 0 0.03" diaginertia="0.001 0.0025 0.0017"/>
                      <geom name="hand_capsule_collision" type="capsule" class="collision" size="0.04 0.06" quat="1 1 0 0" pos="0 0 0.03"/>
                      <site name="gripper" pos="0 0 0.1"/>
                      <body name="camera_d405" pos="0.06 0.0 0.072" quat="0.6830127 0.1830127 -0.1830127 -0.6830127">
                        <geom class="collision" type="box" size=".018 .018 .01" pos="0 0 -0.01"/>
                        <body name="camera_frame" pos="0 0 0" quat="0 0 0 1">
                          <!-- sensorsize="0.00214 0.00214" focal="0.00193 0.00193" -->
                          <!-- <camera name="camera_d405" pos="0 0 -0.013" quat="0 1 0 0" resolution="720 720" fovy="58"/> -->
                        </body>
                      </body>
                      <body name="left_finger" pos="0 0 0.0584">
                        <inertial mass="0.015" pos="0 0 0" diaginertia="2.375e-6 2.375e-6 7.5e-7"/>
                        <joint name="finger_joint1" class="finger" range="0 0.04"/>
                        <geom name="lf1_collision" class="fingertip_collision_1"/>
                        <geom name="lf2_collision" class="fingertip_collision_2"/>
                        <geom name="lf3_collision" class="fingertip_collision_3"/>
                        <geom name="lfp_collision" class="fingertip_pad_collision_6"/>
                      </body>
                      <body name="right_finger" pos="0 0 0.0584" quat="0 0 0 1">
                        <inertial mass="0.015" pos="0 0 0" diaginertia="2.375e-6 2.375e-6 7.5e-7"/>
                        <joint name="finger_joint2" class="finger" range="0 0.04"/>
                        <geom name="rf1_collision" class="fingertip_collision_1"/>
                        <geom name="rf2_collision" class="fingertip_collision_2"/>
                        <geom name="rf3_collision" class="fingertip_collision_3"/>
                        <geom name="rfp_collision" class="fingertip_pad_collision_6"/>
                      </body>
                    </body>
                  </body>
                </body>
              </body>
            </body>
          </body>
        </body>
      </body>
    </body>
  </worldbody>

  <tendon>
    <fixed name="split">
      <joint joint="finger_joint1" coef="0.5"/>
      <joint joint="finger_joint2" coef="0.5"/>
    </fixed>
  </tendon>

  <actuator>
    <general class="panda" name="actuator1" joint="joint1" gainprm="4500" biasprm="0 -4500 -450"/>
    <general class="panda" name="actuator2" joint="joint2" gainprm="4500" biasprm="0 -4500 -450"
      ctrlrange="-1.7628 1.7628"/>
    <general class="panda" name="actuator3" joint="joint3" gainprm="3500" biasprm="0 -3500 -350"/>
    <general class="panda" name="actuator4" joint="joint4" gainprm="3500" biasprm="0 -3500 -350"
      ctrlrange="-3.0718 -0.0698"/>
    <general class="panda" name="actuator5" joint="joint5" gainprm="2000" biasprm="0 -2000 -200" forcerange="-12 12"/>
    <general class="panda" name="actuator6" joint="joint6" gainprm="2000" biasprm="0 -2000 -200" forcerange="-12 12"
      ctrlrange="-0.0175 3.7525"/>
    <general class="panda" name="actuator7" joint="joint7" gainprm="2000" biasprm="0 -2000 -200" forcerange="-12 12"/>
    <!-- Remap original ctrlrange (0, 0.04) to (0, 255): 0.04 * 100 / 255 = 0.01568627451 -->
    <general class="panda" name="actuator8" tendon="split" forcerange="-100 100" ctrlrange="0 255"
      gainprm="0.01568627451 0 0" biasprm="0 -100 -10"/>
  </actuator>

  <keyframe>
    <key name="home" qpos="0 0 0 -1.57079 0 1.57079 0.7853 0.04 0.04" ctrl="0 0 0 -1.57079 0 1.57079 -0.7853 255"/>
  </keyframe>

  <equality>
    <joint joint1="finger_joint1" joint2="finger_joint2" solimp="0.95 0.99 0.001" solref="0.005 1"/>
  </equality>

  <contact>
    <exclude body1="link0" body2="link1"/>
  </contact>
</mujoco>
